Workbook

Sheet DETAILS
B5: Member Name | C5: Phone number | D5: Date | E5: Amount 1 | F5: Type | G5: Date | H5: Amount 2 | I5: Type | J5: Date | K5: Amount 3 | L5: Type | M5: Date | N5: Amount 4 | O5: Type | P5: Date | Q5: Amount 5 | R5: Type | S5: Date | T5: Amount 6 | U5: Type | V5: Date | W5: Amount 7 | X5: Type | Y5: Date | Z5: Amount 8 | AA5: Type | AB5: Date | AC5: Amount 9 | AD5: Type | AE5: Date | AF5: Amount 10 | AG5: Type | AH5: Date | AI5: Amount 11 | AJ5: Type | AK5: Date | AL5: Amount 12 | AM5: Type | AN5: Date | AO5: Amount 13 | AP5: Type | AQ5: Date | AR5: Amount 14 | AS5: Type | AT5: Date | AU5: Amount 15 | AV5: Type | AW5: Grand Total | AX5: Total Socio | AY5: Total Shares | AZ5: Grand Total
A6: 1 | B6: Felix Daniel | D6: 45348 | E6: 1000 | F6: Opening | G6: 45352 | H6: 10000 | I6: Social | J6: 45352 | K6: 60000 | L6: Shares | M6: 45355 | N6: 70000 | O6: Shares | AW6: =E6+H6+K6+N6+Q6+T6+W6+Z6+AC6+AF6+AI6+AO6+AL6+AR6 -> 141000 | AX6: =E6+H6 -> 11000 | AY6: =K6+N6 -> 130000 | AZ6: =AX6+AY6 -> 141000 | BA6: =AZ6=AW6 -> TRUE
A7: 2 | B7: Norbert Massay | D7: 45351 | E7: 50000 | F7: Shares | G7: 45351 | H7: 120000 | I7: Shares | J7: 45351 | K7: 30000 | L7: Social | M7: 45353 | N7: 360000 | O7: Shares | P7: 45354 | Q7: 140000 | R7: Social | S7: 45492 | T7: 100000 | U7: Shares | V7: 45648 | W7: 200000 | X7: Shares | Y7: 45727 | Z7: 100000 | AA7: NMB | AB7: 45728 | AC7: 100000 | AD7: NMB | AW7: =E7+H7+K7+N7+Q7+T7+W7+Z7+AC7+AF7+AI7+AO7+AL7+AR7 -> 1200000 | AX7: =K7+Q7 -> 170000 | AY7: =E7+H7+N7+T7+W7+Z7+AC7 -> 1030000 | AZ7: =AX7+AY7 -> 1200000 | BA7: =AZ7=AW7 -> TRUE
A8: 3 | B8: Mohamed Mohamed | D8: 45352 | E8: 50000 | F8: Shares | G8: 45362 | H8: 120000 | I8: Shares | J8: 45529 | K8: 630000 | L8: Shares | M8: 45654 | N8: 200000 | O8: Shares | AW8: =E8+H8+K8+N8+Q8+T8+W8+Z8+AC8+AF8+AI8+AO8+AL8+AR8 -> 1000000 | AY8: =E8+H8+K8+W7 -> 1000000 | AZ8: =AX8+AY8 -> 1000000 | BA8: =AZ8=AW8 -> TRUE
A9: 4 | B9: Evarist Francisco | D9: 45352 | E9: 90000 | F9: Shares | G9: 45352 | H9: 10000 | I9: Social | J9: 45353 | K9: 50000 | L9: Shares | M9: 45353 | N9: 30000 | O9: Social | P9: 45529 | Q9: 100000 | R9: Shares | S9: 45530 | T9: 100000 | U9: Shares | V9: 45657 | W9: 450000 | X9: Shares | Y9: 45657 | Z9: 170000 | AA9: Shares | AW9: =E9+H9+K9+N9+Q9+T9+W9+Z9+AC9+AF9+AI9+AO9+AL9+AR9 -> 1000000 | AX9: =H9+N9 -> 40000 | AY9: =E9+K9+Q9+T9+W9+Z9 -> 960000 | AZ9: =AX9+AY9 -> 1000000 | BA9: =AZ9=AW9 -> TRUE
A10: 5 | B10: Emmanuel Matee | D10: 45352 | E10: 10000 | F10: Social | G10: 45353 | H10: 20000 | I10: Social | J10: 45353 | K10: 120000 | L10: Shares | M10: 45353 | N10: 50000 | O10: Shares | P10: 45354 | Q10: 50000 | R10: Social | S10: 45394 | T10: 30000 | U10: Social | V10: 45394 | W10: 120000 | X10: Shares | Y10: 45486 | Z10: 20000 | AA10: Social | AB10: 45486 | AC10: 80000 | AD10: Shares | AE10: 45492 | AF10: 40000 | AG10: Social | AH10: 45492 | AI10: =160000+80000 -> 240000 | AJ10: Shares | AK10: 45496 | AL10: 20000 | AM10: Social | AN10: 45648 | AO10: 200000 | AP10: Shares | AQ10: 45690 | AR10: 200000 | AS10: Shares | AT10: 45703 | AU10: 100000 | AV10: Shares | AW10: =E10+H10+K10+N10+Q10+T10+W10+Z10+AC10+AF10+AI10+AO10+AL10+AR10+AU10 -> 1300000 | AX10: =E10+H10+Q10+T10+Z10+AF10+AL10 -> 190000 | AY10: =K10+N10+W10+AC10+AI10+AO10+AR10+AU10 -> 1110000 | AZ10: =AX10+AY10 -> 1300000 | BA10: =AZ10=AW10 -> TRUE
A11: 6 | B11: Innocent Kweka | D11: 45353 | E11: 40000 | F11: Shares | G11: 45353 | H11: 20000 | I11: Social | J11: 45441 | K11: 100000 | L11: Shares | AW11: =E11+H11+K11+N11+Q11+T11+W11+Z11+AC11+AF11+AI11+AO11+AL11+AR11 -> 160000 | AX11: =H11 -> 20000 | AY11: =E11+K11 -> 140000 | AZ11: =AX11+AY11 -> 160000 | BA11: =AZ11=AW11 -> TRUE
A12: 7 | B12: Kanuti Simba | D12: 45354 | E12: 120000 | F12: Social | G12: 45354 | H12: 500000 | I12: Shares | J12: 45363 | K12: 100000 | L12: Shares | M12: 45529 | N12: 80000 | O12: Shares | P12: 45652 | Q12: 200000 | R12: Shares | AW12: =E12+H12+K12+N12+Q12+T12+W12+Z12+AC12+AF12+AI12+AO12+AL12+AR12 -> 1000000 | AX12: =E12 -> 120000 | AY12: =H12+K12+N12+Q12 -> 880000 | AZ12: =AX12+AY12 -> 1000000 | BA12: =AZ12=AW12 -> TRUE
A13: 8 | B13: Evance Mori | D13: 45354 | E13: 100000 | F13: Shares | G13: 45361 | H13: 100000 | I13: Shares | J13: 45411 | K13: 50000 | L13: Social | M13: 45496 | N13: 100000 | O13: Social | P13: 45521 | Q13: 650000 | R13: Shares | AW13: =E13+H13+K13+N13+Q13+T13+W13+Z13+AC13+AF13+AI13+AO13+AL13+AR13 -> 1000000 | AX13: =K13+N13 -> 150000 | AY13: =E13+H13+Q13 -> 850000 | AZ13: =AX13+AY13 -> 1000000 | BA13: =AZ13=AW13 -> TRUE
A14: 9 | B14: Elianshisaria Munisi | D14: 45354 | E14: 150000 | F14: Shares | G14: 45354 | H14: 70000 | I14: Social | J14: 45521 | K14: 900000 | L14: Shares | M14: 45650 | N14: 100000 | O14: Shares | AW14: =E14+H14+K14+N14+Q14+T14+W14+Z14+AC14+AF14+AI14+AO14+AL14+AR14 -> 1220000 | AX14: =H14 -> 70000 | AY14: =E14+K14+N14 -> 1150000 | AZ14: =AX14+AY14 -> 1220000 | BA14: =AZ14=AW14 -> TRUE
A15: 10 | B15: Stephen Nkurlu | D15: 45355 | E15: 50000 | F15: Social | G15: 45355 | H15: 50000 | I15: Shares | J15: 45358 | K15: 120000 | L15: Shares | M15: 45650 | N15: 800000 | O15: Shares | AW15: =E15+H15+K15+N15+Q15+T15+W15+Z15+AC15+AF15+AI15+AO15+AL15+AR15 -> 1020000 | AX15: =E15 -> 50000 | AY15: =H15+K15+N15 -> 970000 | AZ15: =AX15+AY15 -> 1020000 | BA15: =AZ15=AW15 -> TRUE
A16: 11 | B16: Mosses Makoko | D16: 45355 | E16: 170000 | F16: Social | G16: 45355 | H16: 170000 | I16: Shares | J16: 45530 | K16: 460000 | L16: Shares | M16: 45690 | N16: 200000 | O16: Shares | AW16: =E16+H16+K16+N16+Q16+T16+W16+Z16+AC16+AF16+AI16+AO16+AL16+AR16 -> 1000000 | AX16: =E16 -> 170000 | AY16: =H16+K16+N16 -> 830000 | AZ16: =AX16+AY16 -> 1000000 | BA16: =AZ16=AW16 -> TRUE
A17: 12 | B17: Aaron Mtui | D17: 45355 | E17: 100000 | F17: Shares | AW17: =E17+H17+K17+N17+Q17+T17+W17+Z17+AC17+AF17+AI17+AO17+AL17+AR17 -> 100000 | AY17: =E17 -> 100000 | AZ17: =AX17+AY17 -> 100000 | BA17: =AZ17=AW17 -> TRUE
A18: 13 | B18: Jacob Mangu | D18: 45355 | E18: 100000 | F18: Shares | G18: 45359 | H18: 190000 | I18: Shares | J18: 45359 | K18: 110000 | L18: Social | M18: 45359 | N18: 60000 | O18: Social | P18: 45421 | Q18: 140000 | R18: Shares | S18: 45485 | T18: 140000 | U18: Shares | V18: 45504 | W18: 60000 | X18: Shares | Y18: 45649 | Z18: 200000 | AA18: Shares | AB18: 45702 | AC18: 300000 | AD18: Shares | AE18: 45712 | AF18: 300000 | AG18: Shares | AW18: =E18+H18+K18+N18+Q18+T18+W18+Z18+AC18+AF18+AI18+AO18+AL18+AR18 -> 1600000 | AX18: =K18+N18 -> 170000 | AY18: =E18+H18+Q18+T18+W18+Z18+AC18+AF18 -> 1430000 | AZ18: =AX18+AY18 -> 1600000 | BA18: =AZ18=AW18 -> TRUE
A19: 14 | B19: Nsanyiwa Kiloba | D19: 45355 | E19: 170000 | F19: Shares | G19: 45355 | H19: 80000 | I19: Social | J19: 45361 | K19: 170000 | L19: Shares | M19: 45361 | N19: 90000 | O19: Social | P19: 45370 | Q19: 100000 | R19: Shares | S19: 45655 | T19: 400000 | U19: Shares | AW19: =E19+H19+K19+N19+Q19+T19+W19+Z19+AC19+AF19+AI19+AO19+AL19+AR19 -> 1010000 | AX19: =H19+N19 -> 170000 | AY19: =E19+K19+Q19+T19 -> 840000 | AZ19: =AX19+AY19 -> 1010000 | BA19: =AZ19=AW19 -> TRUE
A20: 15 | B20: Ahmad Yahya | D20: 45356 | E20: 50000 | F20: Shares | G20: 45359 | H20: 40000 | I20: Social | J20: 45373 | K20: 50000 | L20: Social | M20: 45373 | N20: 120000 | O20: Shares | P20: 45663 | Q20: 780000 | R20: Shares | AW20: =E20+H20+K20+N20+Q20+T20+W20+Z20+AC20+AF20+AI20+AO20+AL20+AR20 -> 1040000 | AX20: =H20+K20 -> 90000 | AY20: =E20+N20+Q20 -> 950000 | AZ20: =AX20+AY20 -> 1040000 | BA20: =AZ20=AW20 -> TRUE
A21: 16 | B21: Paul Metili | D21: 45356 | E21: 10000 | F21: Social | G21: 45356 | H21: 50000 | I21: Shares | J21: 45356 | K21: 40000 | L21: Social | AW21: =E21+H21+K21+N21+Q21+T21+W21+Z21+AC21+AF21+AI21+AO21+AL21+AR21 -> 100000 | AX21: =E21+K21 -> 50000 | AY21: =H21 -> 50000 | AZ21: =AX21+AY21 -> 100000 | BA21: =AZ21=AW21 -> TRUE
A22: 17 | B22: Patiens Rweyemamu | D22: 45356 | E22: 50000 | F22: Shares | G22: 45356 | H22: 50000 | I22: Social | AW22: =E22+H22+K22+N22+Q22+T22+W22+Z22+AC22+AF22+AI22+AO22+AL22+AR22 -> 100000 | AX22: =H22 -> 50000 | AY22: =E22 -> 50000 | AZ22: =AX22+AY22 -> 100000 | BA22: =AZ22=AW22 -> TRUE
A23: 18 | B23: Elibariki Mkumbo | D23: 45357 | E23: 250000 | F23: Shares | G23: 45365 | H23: 100000 | I23: Social | J23: 45530 | K23: 230000 | L23: Shares | M23: 45687 | N23: 420000 | O23: Shares | AW23: =E23+H23+K23+N23+Q23+T23+W23+Z23+AC23+AF23+AI23+AO23+AL23+AR23 -> 1000000 | AX23: =H23 -> 100000 | AY23: =E23+K23+N23 -> 900000 | AZ23: =AX23+AY23 -> 1000000 | BA23: =AZ23=AW23 -> TRUE
A24: 19 | B24: David Koillah | D24: 45357 | E24: 50000 | F24: Social | G24: 45357 | H24: 50000 | I24: Shares | AW24: =E24+H24+K24+N24+Q24+T24+W24+Z24+AC24+AF24+AI24+AO24+AL24+AR24 -> 100000 | AX24: =E24 -> 50000 | AY24: =H24 -> 50000 | AZ24: =AX24+AY24 -> 100000 | BA24: =AZ24=AW24 -> TRUE
A25: 20 | B25: Innocent Kasigwa | D25: 45357 | E25: 50000 | F25: Shares | G25: 45381 | H25: 150000 | I25: Shares | J25: 45649 | K25: 300000 | L25: Shares | M25: 45659 | N25: 500000 | O25: Shares | AW25: =E25+H25+K25+N25+Q25+T25+W25+Z25+AC25+AF25+AI25+AO25+AL25+AR25 -> 1000000 | AY25: =E25+H25+K25+N25 -> 1000000 | AZ25: =AX25+AY25 -> 1000000 | BA25: =AZ25=AW25 -> TRUE
A26: 21 | B26: Omary Mwasema | D26: 45357 | E26: 50000 | F26: Shares | AW26: =E26+H26+K26+N26+Q26+T26+W26+Z26+AC26+AF26+AI26+AO26+AL26+AR26 -> 50000 | AY26: =E26 -> 50000 | AZ26: =AX26+AY26 -> 50000 | BA26: =AZ26=AW26 -> TRUE
A27: 22 | B27: Erick Kitali | D27: 45357 | E27: 80000 | F27: Social | G27: 45358 | H27: 170000 | I27: Shares | J27: 45525 | K27: 550000 | L27: Shares | M27: 45648 | N27: 200000 | O27: Shares | P27: 45727 | Q27: 300000 | R27: NMB | AW27: =E27+H27+K27+N27+Q27+T27+W27+Z27+AC27+AF27+AI27+AO27+AL27+AR27 -> 1300000 | AX27: =E27 -> 80000 | AY27: =H27+K27+N27+Q27 -> 1220000 | AZ27: =AX27+AY27 -> 1300000 | BA27: =AZ27=AW27 -> TRUE
A28: 23 | B28: Emmanuel Matechi | D28: 45358 | E28: 50000 | F28: Social | G28: 45382 | H28: 50000 | I28: Shares | J28: 45652 | K28: 400000 | L28: Shares | M28: 45656 | N28: 450000 | O28: Shares | P28: 45657 | Q28: 50000 | R28: Shares | AW28: =E28+H28+K28+N28+Q28+T28+W28+Z28+AC28+AF28+AI28+AO28+AL28+AR28 -> 1000000 | AX28: =E28 -> 50000 | AY28: =H28+K28+N28+Q28 -> 950000 | AZ28: =AX28+AY28 -> 1000000 | BA28: =AZ28=AW28 -> TRUE
A29: 24 | B29: Khalifa Sushy | D29: 45359 | E29: 100000 | F29: Social | G29: 45359 | H29: 130000 | I29: Shares | J29: 45383 | K29: 70000 | L29: Social | M29: 45383 | N29: 120000 | O29: Shares | AW29: =E29+H29+K29+N29+Q29+T29+W29+Z29+AC29+AF29+AI29+AO29+AL29+AR29 -> 420000 | AX29: =E29+K29 -> 170000 | AY29: =H29+N29 -> 250000 | AZ29: =AX29+AY29 -> 420000 | BA29: =AZ29=AW29 -> TRUE
A30: 25 | B30: Liggyle Vumilia | D30: 45359 | E30: 50000 | F30: Shares | G30: 45360 | H30: 90000 | I30: Shares | J30: 45360 | K30: 30000 | L30: Social | M30: 45380 | N30: 150000 | O30: Shares | P30: 45380 | Q30: 30000 | R30: Social | AW30: =E30+H30+K30+N30+Q30+T30+W30+Z30+AC30+AF30+AI30+AO30+AL30+AR30 -> 350000 | AX30: =K30+Q30 -> 60000 | AY30: =E30+H30+N30 -> 290000 | AZ30: =AX30+AY30 -> 350000 | BA30: =AZ30=AW30 -> TRUE
A31: 26 | B31: Ernest Shirima | D31: 45360 | E31: 290000 | F31: Shares | G31: 45360 | H31: 110000 | I31: Social | J31: 45523 | K31: 340000 | L31: Shares | M31: 45523 | N31: 60000 | O31: Social | AW31: =E31+H31+K31+N31+Q31+T31+W31+Z31+AC31+AF31+AI31+AO31+AL31+AR31 -> 800000 | AX31: =H31+N31 -> 170000 | AY31: =E31+K31 -> 630000 | AZ31: =AX31+AY31 -> 800000 | BA31: =AZ31=AW31 -> TRUE
A32: 27 | B32: Walter Salema | D32: 45360 | E32: 60000 | F32: Social | G32: 45360 | H32: 90000 | I32: Shares | J32: 45526 | K32: 650000 | L32: Shares | AW32: =E32+H32+K32+N32+Q32+T32+W32+Z32+AC32+AF32+AI32+AO32+AL32+AR32 -> 800000 | AX32: =E32 -> 60000 | AY32: =H32+K32 -> 740000 | AZ32: =AX32+AY32 -> 800000 | BA32: =AZ32=AW32 -> TRUE
A33: 28 | B33: Stanslaus Nyembea | D33: 45360 | E33: 120000 | F33: Shares | AW33: =E33+H33+K33+N33+Q33+T33+W33+Z33+AC33+AF33+AI33+AO33+AL33+AR33 -> 120000 | AY33: =E33 -> 120000 | AZ33: =AX33+AY33 -> 120000 | BA33: =AZ33=AW33 -> TRUE
A34: 29 | B34: Abraham Assenga | D34: 45360 | E34: 90000 | F34: Shares | G34: 45360 | H34: 60000 | I34: Social | J34: 45530 | K34: 600000 | L34: Shares | M34: 45530 | N34: 200000 | O34: Shares | P34: 45657 | Q34: 50000 | R34: Shares | AW34: =E34+H34+K34+N34+Q34+T34+W34+Z34+AC34+AF34+AI34+AO34+AL34+AR34 -> 1000000 | AX34: =H34 -> 60000 | AY34: =E34+K34+N34+Q34 -> 940000 | AZ34: =AX34+AY34 -> 1000000 | BA34: =AZ34=AW34 -> TRUE
A35: 30 | B35: Abduel Kitururu | D35: 45361 | E35: 280000 | F35: Shares | G35: 45361 | H35: 70000 | I35: Social | J35: 45361 | K35: 280000 | L35: Shares | AW35: =E35+H35+K35+N35+Q35+T35+W35+Z35+AC35+AF35+AI35+AO35+AL35+AR35 -> 630000 | AX35: =H35 -> 70000 | AY35: =E35+K35 -> 560000 | AZ35: =AX35+AY35 -> 630000 | BA35: =AZ35=AW35 -> TRUE
A36: 31 | B36: Masale Masale | D36: 45361 | E36: 100000 | F36: Social | G36: 45361 | H36: 250000 | I36: Shares | J36: 45637 | K36: 450000 | L36: Shares | M36: 45650 | N36: 200000 | O36: Shares | AW36: =E36+H36+K36+N36+Q36+T36+W36+Z36+AC36+AF36+AI36+AO36+AL36+AR36 -> 1000000 | AX36: =E36 -> 100000 | AY36: =H36+K36+N36 -> 900000 | AZ36: =AX36+AY36 -> 1000000 | BA36: =AZ36=AW36 -> TRUE
A37: 32 | B37: Bakari Hemedi | D37: 45361 | E37: 50000 | F37: Shares | G37: 45361 | H37: 50000 | I37: Social | J37: 45669 | K37: 1000000 | L37: Shares | AW37: =E37+H37+K37+N37+Q37+T37+W37+Z37+AC37+AF37+AI37+AO37+AL37+AR37 -> 1100000 | AX37: =H37 -> 50000 | AY37: =E37+K37 -> 1050000 | AZ37: =AX37+AY37 -> 1100000 | BA37: =AZ37=AW37 -> TRUE
A38: 33 | B38: Athumani Mwasha | D38: 45363 | E38: 170000 | F38: Social | G38: 45363 | H38: 130000 | I38: Shares | J38: 45524 | K38: 220000 | L38: Shares | M38: 45530 | N38: 280000 | O38: Shares | P38: 45659 | Q38: 200000 | R38: Shares | AW38: =E38+H38+K38+N38+Q38+T38+W38+Z38+AC38+AF38+AI38+AO38+AL38+AR38 -> 1000000 | AX38: =E38 -> 170000 | AY38: =H38+K38+N38+Q38 -> 830000 | AZ38: =AX38+AY38 -> 1000000 | BA38: =AZ38=AW38 -> TRUE
A39: 34 | B39: Nalogwa Kiula | D39: 45363 | E39: 50000 | F39: Social | AW39: =E39+H39+K39+N39+Q39+T39+W39+Z39+AC39+AF39+AI39+AO39+AL39+AR39 -> 50000 | AX39: =E39 -> 50000 | AZ39: =AX39+AY39 -> 50000 | BA39: =AZ39=AW39 -> TRUE
A40: 35 | B40: Best Magoma | D40: 45363 | E40: 50000 | F40: Social | G40: 45382 | H40: 100000 | I40: Shares | J40: 45487 | K40: 100000 | L40: Shares | M40: 45652 | N40: 200000 | O40: Shares | P40: 45656 | Q40: 550000 | R40: Shares | AW40: =E40+H40+K40+N40+Q40+T40+W40+Z40+AC40+AF40+AI40+AO40+AL40+AR40 -> 1000000 | AX40: =E40 -> 50000 | AY40: =H40+K40+N40+Q40 -> 950000 | AZ40: =AX40+AY40 -> 1000000 | BA40: =AZ40=AW40 -> TRUE
A41: 36 | B41: Gideon Gabriel | D41: 45369 | E41: 80000 | F41: Social | G41: 45369 | H41: 90000 | I41: Shares | J41: 45683 | K41: 200000 | L41: Shares | AW41: =E41+H41+K41+N41+Q41+T41+W41+Z41+AC41+AF41+AI41+AO41+AL41+AR41 -> 370000 | AX41: =E41 -> 80000 | AY41: =H41+K41 -> 290000 | AZ41: =AX41+AY41 -> 370000 | BA41: =AZ41=AW41 -> TRUE
A42: 37 | B42: Amos Nungu | D42: 45369 | E42: 220000 | F42: Shares | G42: 45369 | H42: 80000 | I42: Social | J42: 45524 | K42: 550000 | L42: Shares | M42: 45683 | N42: 150000 | O42: Shares | AW42: =E42+H42+K42+N42+Q42+T42+W42+Z42+AC42+AF42+AI42+AO42+AL42+AR42 -> 1000000 | AX42: =H42 -> 80000 | AY42: =E42+K42+N42 -> 920000 | AZ42: =AX42+AY42 -> 1000000 | BA42: =AZ42=AW42 -> TRUE
A43: 38 | B43: Mlindwa Kashindye | D43: 45369 | E43: 150000 | F43: Social | G43: 45370 | H43: 20000 | I43: Social | J43: 45370 | K43: 200000 | L43: Shares | M43: 45382 | N43: 130000 | O43: Shares | P43: 45525 | Q43: 300000 | R43: Shares | S43: 45635 | T43: 200000 | U43: Shares | V43: 45659 | W43: 250000 | X43: Shares | AW43: =E43+H43+K43+N43+Q43+T43+W43+Z43+AC43+AF43+AI43+AO43+AL43+AR43 -> 1250000 | AX43: =E43+H43 -> 170000 | AY43: =K43+N43+Q43+T43+W43 -> 1080000 | AZ43: =AX43+AY43 -> 1250000 | BA43: =AZ43=AW43 -> TRUE
A44: 39 | B44: Emmanuel Msaki | D44: 45369 | E44: 63000 | F44: Shares | G44: 45392 | H44: 50000 | I44: Shares | J44: 45635 | K44: 100000 | L44: Shares | M44: 45653 | N44: 300000 | O44: Shares | AW44: =E44+H44+K44+N44+Q44+T44+W44+Z44+AC44+AF44+AI44+AO44+AL44+AR44 -> 513000 | AY44: =E44+H44+K44+N44 -> 513000 | AZ44: =AX44+AY44 -> 513000 | BA44: =AZ44=AW44 -> TRUE
...

Sheet Sheet1
B2: Amounts in the NMB BANK
B3: Date | C3: Name | D3: Amount
B4: ='DETAILS (sorted)'!AE45 -> 0 | C4: ='DETAILS (sorted)'!B45 -> Abduel Kitururu | D4: ='DETAILS (sorted)'!AF45 -> 0

Sheet Summary
A1: ILBORU ALUMNI SACCOS LIMITED
A3: MICHANGO YA WANACHAMA
A6: S/N | B6: Member Name | C6: MICHANGO | I6: KIWANGO KINACHOHITAJIKA | K6: KIWANGO CHA KUKAMILISHA | M6: STATUS | N6: GAHRAMA ZA MIKUTANO [allocated already]
C7: KIINGILIO | D7: AKIBA | E7: HISA | F7: JUMLA | H7: ACTUAL | Q7: OCTOBER, 2024 | R7: NOV, 2024 | S7: DEC, 2024 | T7: JAN, 2025 | U7: FEB, 2025
D8: ALLOCATED FROM M-KOBA | E8: ALLOCATED FROM M-KOBA | H8: MKOBA | L8: BADO
A9: 1 | B9: Aaron J. Mtui | C9: 100000 | F9: =SUM(C9:E9) -> 100000 | G9: =F9=H9 -> TRUE | H9: =DETAILS!AZ17 -> 100000 | I9: 1200000 | J9: =H9/I9 -> 0.083333333 | K9: =MAX(I9-H9,0) -> 1100000 | L9: =100%-J9 -> 0.91666667 | M9: WAMESHASAINI MAKABRASHA YA USAJILI. LAKINI WENGI HAWAJAMALIZIA MICHANGO YAO | O9: =F9=H9 -> TRUE
A10: =A9+1 -> 2 | B10: Abduel G. Kitururu | C10: 200000 | D10: 100000 | E10: 330000 | F10: =SUM(C10:E10) -> 630000 | G10: =F10=H10 -> TRUE | H10: =DETAILS!AZ35 -> 630000 | I10: 1200000 | J10: =H10/I10 -> 0.525 | K10: =MAX(I10-H10,0) -> 570000 | L10: =100%-J10 -> 0.475 | O10: =F10=H10 -> TRUE
A11: =A10+1 -> 3 | B11: Abraham A. Assenga | C11: 200000 | D11: 100000 | E11: 700000 | F11: =SUM(C11:E11) -> 1000000 | G11: =F11=H11 -> TRUE | H11: =DETAILS!AZ34 -> 1000000 | I11: 1200000 | J11: =H11/I11 -> 0.83333333 | K11: =MAX(I11-H11,0) -> 200000 | L11: =100%-J11 -> 0.16666667 | O11: =F11=H11 -> TRUE | P11: 1
A12: =A11+1 -> 4 | B12: Adam I. Urassa | C12: 200000 | D12: 100000 | E12: 700000 | F12: =SUM(C12:E12) -> 1000000 | G12: =F12=H12 -> TRUE | H12: =DETAILS!AW56 -> 1000000 | I12: 1200000 | J12: =H12/I12 -> 0.83333333 | K12: =MAX(I12-H12,0) -> 200000 | L12: =100%-J12 -> 0.16666667 | O12: =F12=H12 -> TRUE | P12: 1
A13: =A12+1 -> 5 | B13: Amos M. Nungu | C13: 200000 | D13: 100000 | E13: 700000 | F13: =SUM(C13:E13) -> 1000000 | G13: =F13=H13 -> TRUE | H13: =DETAILS!AW42 -> 1000000 | I13: 1200000 | J13: =H13/I13 -> 0.83333333 | K13: =MAX(I13-H13,0) -> 200000 | L13: =100%-J13 -> 0.16666667 | O13: =F13=H13 -> TRUE | P13: 1
A14: =A13+1 -> 6 | B14: Athumani Jerry Mwasha | C14: 200000 | D14: 100000 | E14: 700000 | F14: =SUM(C14:E14) -> 1000000 | G14: =F14=H14 -> TRUE | H14: =DETAILS!AW38 -> 1000000 | I14: 1200000 | J14: =H14/I14 -> 0.83333333 | K14: =MAX(I14-H14,0) -> 200000 | L14: =100%-J14 -> 0.16666667 | O14: =F14=H14 -> TRUE | P14: 1
A15: =A14+1 -> 7 | B15: Elianshisaria Invocavith Munisi | C15: 200000 | D15: 100000 | E15: 920000 | F15: =SUM(C15:E15) -> 1220000 | G15: =F15=H15 -> TRUE | H15: =DETAILS!AW14 -> 1220000 | I15: 1200000 | J15: =H15/I15 -> 1.0166667 | K15: =MAX(I15-H15,0) -> 0 | L15: =100%-J15 -> -0.016666667 | N15: 10000 | O15: =F15=H15 -> TRUE | P15: 1
A16: =A15+1 -> 8 | B16: Elibariki Mkumbo | C16: 200000 | D16: 100000 | E16: 700000 | F16: =SUM(C16:E16) -> 1000000 | G16: =F16=H16 -> TRUE | H16: =DETAILS!AW23 -> 1000000 | I16: 1200000 | J16: =H16/I16 -> 0.83333333 | K16: =MAX(I16-H16,0) -> 200000 | L16: =100%-J16 -> 0.16666667 | O16: =F16=H16 -> TRUE | P16: 1
A17: =A16+1 -> 9 | B17: Emmanuel Matechi | C17: 200000 | D17: 100000 | E17: 700000 | F17: =SUM(C17:E17) -> 1000000 | G17: =F17=H17 -> TRUE | H17: =DETAILS!AW28 -> 1000000 | I17: 1200000 | J17: =H17/I17 -> 0.83333333 | K17: =MAX(I17-H17,0) -> 200000 | L17: =100%-J17 -> 0.16666667 | O17: =F17=H17 -> TRUE | P17: 1
A18: =A17+1 -> 10 | B18: Emmanuel Matee | C18: 200000 | D18: 100000 | E18: 1000000 | F18: =SUM(C18:E18) -> 1300000 | G18: =F18=H18 -> TRUE | H18: =DETAILS!AW10 -> 1300000 | I18: 1200000 | J18: =H18/I18 -> 1.0833333 | K18: =MAX(I18-H18,0) -> 0 | L18: =100%-J18 -> -0.083333333 | O18: =F18=H18 -> TRUE | P18: 1
A19: =A18+1 -> 11 | B19: Emmanuel Mmari | C19: 200000 | D19: 100000 | E19: 700000 | F19: =SUM(C19:E19) -> 1000000 | G19: =F19=H19 -> TRUE | H19: =DETAILS!AW58 -> 1000000 | I19: 1200000 | J19: =H19/I19 -> 0.83333333 | K19: =MAX(I19-H19,0) -> 200000 | L19: =100%-J19 -> 0.16666667 | O19: =F19=H19 -> TRUE | P19: 1
A20: =A19+1 -> 12 | B20: Erick Kitali | C20: 200000 | D20: 100000 | E20: 1000000 | F20: =SUM(C20:E20) -> 1300000 | G20: =F20=H20 -> TRUE | H20: =DETAILS!AW27 -> 1300000 | I20: 1200000 | J20: =H20/I20 -> 1.0833333 | K20: =MAX(I20-H20,0) -> 0 | L20: =100%-J20 -> -0.083333333 | O20: =F20=H20 -> TRUE | P20: 1
A21: =A20+1 -> 13 | B21: Ernest Felician Shirima | C21: 200000 | D21: 100000 | E21: 500000 | F21: =SUM(C21:E21) -> 800000 | G21: =F21=H21 -> TRUE | H21: =DETAILS!AW31 -> 800000 | I21: 1200000 | J21: =H21/I21 -> 0.66666667 | K21: =MAX(I21-H21,0) -> 400000 | L21: =100%-J21 -> 0.33333333 | O21: =F21=H21 -> TRUE
A22: =A21+1 -> 14 | B22: Evarist Exavery Francisco | C22: 200000 | D22: 100000 | E22: 700000 | F22: =SUM(C22:E22) -> 1000000 | G22: =F22=H22 -> TRUE | H22: =DETAILS!AW9 -> 1000000 | I22: 1200000 | J22: =H22/I22 -> 0.83333333 | K22: =MAX(I22-H22,0) -> 200000 | L22: =100%-J22 -> 0.16666667 | O22: =F22=H22 -> TRUE | P22: 1
A23: =A22+1 -> 15 | B23: Fredrick Peter Ndossi | C23: 200000 | D23: 100000 | E23: 700000 | F23: =SUM(C23:E23) -> 1000000 | G23: =F23=H23 -> TRUE | H23: =DETAILS!AW51 -> 1000000 | I23: 1200000 | J23: =H23/I23 -> 0.83333333 | K23: =MAX(I23-H23,0) -> 200000 | L23: =100%-J23 -> 0.16666667 | N23: 10000 | O23: =F23=H23 -> TRUE | P23: 1
A24: =A23+1 -> 16 | B24: Kanuti S. Simba | C24: 200000 | D24: 100000 | E24: 700000 | F24: =SUM(C24:E24) -> 1000000 | G24: =F24=H24 -> TRUE | H24: =DETAILS!AW12 -> 1000000 | I24: 1200000 | J24: =H24/I24 -> 0.83333333 | K24: =MAX(I24-H24,0) -> 200000 | L24: =100%-J24 -> 0.16666667 | O24: =F24=H24 -> TRUE | P24: 1
A25: =A24+1 -> 17 | B25: Mlindwa S. Kashindye | C25: 200000 | D25: 100000 | E25: 950000 | F25: =SUM(C25:E25) -> 1250000 | G25: =F25=H25 -> TRUE | H25: =DETAILS!AW43 -> 1250000 | I25: 1200000 | J25: =H25/I25 -> 1.0416667 | K25: =MAX(I25-H25,0) -> 0 | L25: =100%-J25 -> -0.041666667 | O25: =F25=H25 -> TRUE | P25: 1
A26: =A25+1 -> 18 | B26: Mohamed K. Mohamed | C26: 200000 | D26: 100000 | E26: 700000 | F26: =SUM(C26:E26) -> 1000000 | G26: =F26=H26 -> TRUE | H26: =DETAILS!AW8 -> 1000000 | I26: 1200000 | J26: =H26/I26 -> 0.83333333 | K26: =MAX(I26-H26,0) -> 200000 | L26: =100%-J26 -> 0.16666667 | O26: =F26=H26 -> TRUE | P26: 1
A27: =A26+1 -> 19 | B27: Mosses Makoko | C27: 200000 | D27: 100000 | E27: 700000 | F27: =SUM(C27:E27) -> 1000000 | G27: =F27=H27 -> TRUE | H27: =DETAILS!AW16 -> 1000000 | I27: 1200000 | J27: =H27/I27 -> 0.83333333 | K27: =MAX(I27-H27,0) -> 200000 | L27: =100%-J27 -> 0.16666667 | O27: =F27=H27 -> TRUE | P27: 1
A28: =A27+1 -> 20 | B28: Nsanyiwa Kiloba | C28: 200000 | D28: 100000 | E28: 710000 | F28: =SUM(C28:E28) -> 1010000 | G28: =F28=H28 -> TRUE | H28: =DETAILS!AW19 -> 1010000 | I28: 1200000 | J28: =H28/I28 -> 0.84166667 | K28: =MAX(I28-H28,0) -> 190000 | L28: =100%-J28 -> 0.15833333 | O28: =F28=H28 -> TRUE | P28: 1 | Q28: 235000
A29: =A28+1 -> 21 | B29: Abdillahi Moshi | C29: 200000 | D29: 100000 | E29: 700000 | F29: =SUM(C29:E29) -> 1000000 | G29: =F29=H29 -> TRUE | H29: =DETAILS!AW48 -> 1000000 | I29: 1200000 | J29: =H29/I29 -> 0.83333333 | K29: =MAX(I29-H29,0) -> 200000 | L29: =100%-J29 -> 0.16666667 | M29: WAMELIPA SEHEMU YA MICHANGO ILA HAWAJASAINI MAKABRASHA YA USAJILI | O29: =F29=H29 -> TRUE | P29: 1
A30: =A29+1 -> 22 | B30: Ahmad Yahya | C30: 200000 | D30: 100000 | E30: 740000 | F30: =SUM(C30:E30) -> 1040000 | G30: =F30=H30 -> TRUE | H30: =DETAILS!AW20 -> 1040000 | I30: 1200000 | J30: =H30/I30 -> 0.86666667 | K30: =MAX(I30-H30,0) -> 160000 | L30: =100%-J30 -> 0.13333333 | O30: =F30=H30 -> TRUE | P30: 1
A31: =A30+1 -> 23 | B31: Albani Kimario | C31: 200000 | D31: 100000 | E31: 700000 | F31: =SUM(C31:E31) -> 1000000 | G31: =F31=H31 -> TRUE | H31: =DETAILS!AW50 -> 1000000 | I31: 1200000 | J31: =H31/I31 -> 0.83333333 | K31: =MAX(I31-H31,0) -> 200000 | L31: =100%-J31 -> 0.16666667 | O31: =F31=H31 -> TRUE | P31: 1
A32: =A31+1 -> 24 | B32: Bakari Hemedi | C32: 200000 | D32: 100000 | E32: 800000 | F32: =SUM(C32:E32) -> 1100000 | G32: =F32=H32 -> TRUE | H32: =DETAILS!AW37 -> 1100000 | I32: 1200000 | J32: =H32/I32 -> 0.91666667 | K32: =MAX(I32-H32,0) -> 100000 | L32: =100%-J32 -> 0.083333333 | O32: =F32=H32 -> TRUE | P32: 1
A33: =A32+1 -> 25 | B33: Best Magoma | C33: 200000 | D33: 100000 | E33: 700000 | F33: =SUM(C33:E33) -> 1000000 | G33: =F33=H33 -> TRUE | H33: =DETAILS!AW40 -> 1000000 | I33: 1200000 | J33: =H33/I33 -> 0.83333333 | K33: =MAX(I33-H33,0) -> 200000 | L33: =100%-J33 -> 0.16666667 | O33: =F33=H33 -> TRUE | P33: 1
A34: =A33+1 -> 26 | B34: Charles Jangu | C34: 200000 | D34: 100000 | E34: 400000 | F34: =SUM(C34:E34) -> 700000 | G34: =F34=H34 -> TRUE | H34: =DETAILS!AW52 -> 700000 | I34: 1200000 | J34: =H34/I34 -> 0.58333333 | K34: =MAX(I34-H34,0) -> 500000 | L34: =100%-J34 -> 0.41666667 | O34: =F34=H34 -> TRUE
A35: =A34+1 -> 27 | B35: David Koillah | C35: 100000 | F35: =SUM(C35:E35) -> 100000 | G35: =F35=H35 -> TRUE | H35: =DETAILS!AW24 -> 100000 | I35: 1200000 | J35: =H35/I35 -> 0.083333333 | K35: =MAX(I35-H35,0) -> 1100000 | L35: =100%-J35 -> 0.91666667 | O35: =F35=H35 -> TRUE
A36: =A35+1 -> 28 | B36: Emmanuel Msaki | C36: 200000 | D36: 100000 | E36: 213000 | F36: =SUM(C36:E36) -> 513000 | G36: =F36=H36 -> TRUE | H36: =DETAILS!AW44 -> 513000 | I36: 1200000 | J36: =H36/I36 -> 0.4275 | K36: =MAX(I36-H36,0) -> 687000 | L36: =100%-J36 -> 0.5725 | O36: =F36=H36 -> TRUE
A37: =A36+1 -> 29 | B37: Evance Mori | C37: 200000 | D37: 100000 | E37: 700000 | F37: =SUM(C37:E37) -> 1000000 | G37: =F37=H37 -> TRUE | H37: =DETAILS!AW13 -> 1000000 | I37: 1200000 | J37: =H37/I37 -> 0.83333333 | K37: =MAX(I37-H37,0) -> 200000 | L37: =100%-J37 -> 0.16666667 | O37: =F37=H37 -> TRUE | P37: 1
A38: =A37+1 -> 30 | B38: Felix Daniel | C38: 141000 | F38: =SUM(C38:E38) -> 141000 | G38: =F38=H38 -> TRUE | H38: =DETAILS!AW6 -> 141000 | I38: 1200000 | J38: =H38/I38 -> 0.1175 | K38: =MAX(I38-H38,0) -> 1059000 | L38: =100%-J38 -> 0.8825 | O38: =F38=H38 -> TRUE
A39: =A38+1 -> 31 | B39: Gideon Gabriel | C39: 200000 | D39: 100000 | E39: 70000 | F39: =SUM(C39:E39) -> 370000 | G39: =F39=H39 -> TRUE | H39: =DETAILS!AW41 -> 370000 | I39: 1200000 | J39: =H39/I39 -> 0.30833333 | K39: =MAX(I39-H39,0) -> 830000 | L39: =100%-J39 -> 0.69166667 | O39: =F39=H39 -> TRUE
A40: =A39+1 -> 32 | B40: Hassan Matata | C40: 200000 | D40: 100000 | E40: 700000 | F40: =SUM(C40:E40) -> 1000000 | G40: =F40=H40 -> TRUE | H40: =DETAILS!AW53 -> 1000000 | I40: 1200000 | J40: =H40/I40 -> 0.83333333 | K40: =MAX(I40-H40,0) -> 200000 | L40: =100%-J40 -> 0.16666667 | O40: =F40=H40 -> TRUE | P40: 1
A41: =A40+1 -> 33 | B41: Innocent Kasigwa | C41: 200000 | D41: 100000 | E41: 700000 | F41: =SUM(C41:E41) -> 1000000 | G41: =F41=H41 -> TRUE | H41: =DETAILS!AW25 -> 1000000 | I41: 1200000 | J41: =H41/I41 -> 0.83333333 | K41: =MAX(I41-H41,0) -> 200000 | L41: =100%-J41 -> 0.16666667 | O41: =F41=H41 -> TRUE | P41: 1
A42: =A41+1 -> 34 | B42: Innocent Kweka | C42: 160000 | F42: =SUM(C42:E42) -> 160000 | G42: =F42=H42 -> TRUE | H42: =DETAILS!AW11 -> 160000 | I42: 1200000 | J42: =H42/I42 -> 0.13333333 | K42: =MAX(I42-H42,0) -> 1040000 | L42: =100%-J42 -> 0.86666667 | O42: =F42=H42 -> TRUE
A43: =A42+1 -> 35 | B43: Jacob Mangu | C43: 200000 | D43: 100000 | E43: 1300000 | F43: =SUM(C43:E43) -> 1600000 | G43: =F43=H43 -> TRUE | H43: =DETAILS!AW18 -> 1600000 | I43: 1200000 | J43: =H43/I43 -> 1.3333333 | K43: =MAX(I43-H43,0) -> 0 | L43: =100%-J43 -> -0.33333333 | O43: =F43=H43 -> TRUE | P43: 1
...

Sheet Summary (sorted)
A1: ILBORU ALUMNI SACCOS LIMITED
A3: MICHANGO YA WANACHAMA
A6: S/N | B6: Member Name | C6: MICHANGO | I6: KIWANGO KINACHOHITAJIKA | K6: KIWANGO CHA KUKAMILISHA | M6: STATUS | N6: GAHRAMA ZA MIKUTANO [allocated already]
C7: KIINGILIO | D7: AKIBA | E7: HISA | F7: JUMLA | H7: ACTUAL | Q7: OCTOBER, 2024
D8: ALLOCATED FROM M-KOBA | E8: ALLOCATED FROM M-KOBA | H8: MKOBA | L8: BADO
A9: 1 | B9: Aaron J. Mtui | C9: 100000 | F9: =SUM(C9:E9) -> 100000 | G9: =F9=H9 -> FALSE | H9: ='DETAILS (sorted)'!BI2 -> 2200000 | I9: 1700000 | J9: =H9/I9 -> 1.2941176 | K9: =MAX(I9-H9,0) -> 0 | L9: =100%-J9 -> -0.29411765 | M9: WAMESHASAINI MAKABRASHA YA USAJILI. LAKINI WENGI HAWAJAMALIZIA MICHANGO YAO | O9: =F9=H9 -> FALSE | R9: NOV, 2024 | S9: DEC, 2024 | T9: JAN, 2025 | U9: FEB, 2025
A10: =A9+1 -> 2 | B10: Abdillahi Moshi | C10: 200000 | D10: 100000 | E10: 700000 | F10: =SUM(C10:E10) -> 1000000 | G10: =F10=H10 -> FALSE | H10: ='DETAILS (sorted)'!BI3 -> 3500000 | I10: 1700000 | J10: =H10/I10 -> 2.0588235 | K10: =MAX(I10-H10,0) -> 0 | L10: =100%-J10 -> -1.0588235 | M10: WAMELIPA SEHEMU YA MICHANGO ILA HAWAJASAINI MAKABRASHA YA USAJILI | O10: =F10=H10 -> FALSE | P10: 1
A11: =A10+1 -> 3 | B11: Abduel G. Kitururu | C11: 200000 | D11: 100000 | E11: 330000 | F11: =SUM(C11:E11) -> 630000 | G11: =F11=H11 -> FALSE | H11: ='DETAILS (sorted)'!BI4 -> 1900000 | I11: 1700000 | J11: =H11/I11 -> 1.1176471 | K11: =MAX(I11-H11,0) -> 0 | L11: =100%-J11 -> -0.11764706 | O11: =F11=H11 -> FALSE
A12: =A11+1 -> 4 | B12: Abraham A. Assenga | C12: 200000 | D12: 100000 | E12: 700000 | F12: =SUM(C12:E12) -> 1000000 | G12: =F12=H12 -> TRUE | H12: ='DETAILS (sorted)'!BI5 -> 1000000 | I12: 1700000 | J12: =H12/I12 -> 0.58823529 | K12: =MAX(I12-H12,0) -> 700000 | L12: =100%-J12 -> 0.41176471 | O12: =F12=H12 -> TRUE | P12: 1
A13: =A12+1 -> 5 | B13: Adam I. Urassa | C13: 200000 | D13: 100000 | E13: 700000 | F13: =SUM(C13:E13) -> 1000000 | G13: =F13=H13 -> FALSE | H13: ='DETAILS (sorted)'!BI6 -> 2000000 | I13: 1700000 | J13: =H13/I13 -> 1.1764706 | K13: =MAX(I13-H13,0) -> 0 | L13: =100%-J13 -> -0.17647059 | O13: =F13=H13 -> FALSE | P13: 1
A14: =A13+1 -> 6 | B14: Adolph Ndyeabura | C14: 200000 | D14: 100000 | E14: 700000 | F14: =SUM(C14:E14) -> 1000000 | G14: =F14=H14 -> FALSE | H14: ='DETAILS (sorted)'!BI7 -> 2000000 | I14: 1700000 | J14: =H14/I14 -> 1.1764706 | K14: =MAX(I14-H14,0) -> 0 | L14: =100%-J14 -> -0.17647059 | P14: 1
A15: =A14+1 -> 7 | B15: Ahmad Yahya | C15: 200000 | D15: 100000 | E15: 740000 | F15: =SUM(C15:E15) -> 1040000 | G15: =F15=H15 -> FALSE | H15: ='DETAILS (sorted)'!BI8 -> 2300000 | I15: 1700000 | J15: =H15/I15 -> 1.3529412 | K15: =MAX(I15-H15,0) -> 0 | L15: =100%-J15 -> -0.35294118 | O15: =F15=H15 -> FALSE | P15: 1
A16: =A15+1 -> 8 | B16: Albani Kimario | C16: 200000 | D16: 100000 | E16: 700000 | F16: =SUM(C16:E16) -> 1000000 | G16: =F16=H16 -> FALSE | H16: ='DETAILS (sorted)'!BI9 -> 141000 | I16: 1700000 | J16: =H16/I16 -> 0.082941176 | K16: =MAX(I16-H16,0) -> 1559000 | L16: =100%-J16 -> 0.91705882 | O16: =F16=H16 -> FALSE | P16: 1
A17: =A16+1 -> 9 | B17: Amos M. Nungu | C17: 200000 | D17: 100000 | E17: 700000 | F17: =SUM(C17:E17) -> 1000000 | G17: =F17=H17 -> FALSE | H17: ='DETAILS (sorted)'!BI10 -> 1170000 | I17: 1700000 | J17: =H17/I17 -> 0.68823529 | K17: =MAX(I17-H17,0) -> 530000 | L17: =100%-J17 -> 0.31176471 | O17: =F17=H17 -> FALSE | P17: 1
A18: =A17+1 -> 10 | B18: Athumani Jerry Mwasha | C18: 200000 | D18: 100000 | E18: 700000 | F18: =SUM(C18:E18) -> 1000000 | G18: =F18=H18 -> FALSE | H18: ='DETAILS (sorted)'!BI11 -> 2000000 | I18: 1700000 | J18: =H18/I18 -> 1.1764706 | K18: =MAX(I18-H18,0) -> 0 | L18: =100%-J18 -> -0.17647059 | O18: =F18=H18 -> FALSE | P18: 1
A19: =A18+1 -> 11 | B19: Bakari Hemedi | C19: 200000 | D19: 100000 | E19: 800000 | F19: =SUM(C19:E19) -> 1100000 | G19: =F19=H19 -> FALSE | H19: ='DETAILS (sorted)'!BI12 -> 2400000 | I19: 1700000 | J19: =H19/I19 -> 1.4117647 | K19: =MAX(I19-H19,0) -> 0 | L19: =100%-J19 -> -0.41176471 | O19: =F19=H19 -> FALSE | P19: 1
A20: =A19+1 -> 12 | B20: Best Magoma | C20: 200000 | D20: 100000 | E20: 700000 | F20: =SUM(C20:E20) -> 1000000 | G20: =F20=H20 -> FALSE | H20: ='DETAILS (sorted)'!BI13 -> 1900000 | I20: 1700000 | J20: =H20/I20 -> 1.1176471 | K20: =MAX(I20-H20,0) -> 0 | L20: =100%-J20 -> -0.11764706 | O20: =F20=H20 -> FALSE | P20: 1
A21: =A20+1 -> 13 | B21: Charles Jangu | C21: 200000 | D21: 100000 | E21: 400000 | F21: =SUM(C21:E21) -> 700000 | G21: =F21=H21 -> FALSE | H21: ='DETAILS (sorted)'!BI14 -> 1500000 | I21: 1700000 | J21: =H21/I21 -> 0.88235294 | K21: =MAX(I21-H21,0) -> 200000 | L21: =100%-J21 -> 0.11764706 | O21: =F21=H21 -> FALSE
A22: =A21+1 -> 14 | B22: David Koillah | C22: 100000 | F22: =SUM(C22:E22) -> 100000 | G22: =F22=H22 -> FALSE | H22: ='DETAILS (sorted)'!BI15 -> 2000000 | I22: 1700000 | J22: =H22/I22 -> 1.1764706 | K22: =MAX(I22-H22,0) -> 0 | L22: =100%-J22 -> -0.17647059 | O22: =F22=H22 -> FALSE
A23: =A22+1 -> 15 | B23: Elianshisaria Invocavith Munisi | C23: 200000 | D23: 100000 | E23: 920000 | F23: =SUM(C23:E23) -> 1220000 | G23: =F23=H23 -> FALSE | H23: ='DETAILS (sorted)'!BI16 -> 1600000 | I23: 1700000 | J23: =H23/I23 -> 0.94117647 | K23: =MAX(I23-H23,0) -> 100000 | L23: =100%-J23 -> 0.058823529 | N23: 10000 | O23: =F23=H23 -> FALSE | P23: 1
A24: =A23+1 -> 16 | B24: Elibariki Mkumbo | C24: 200000 | D24: 100000 | E24: 700000 | F24: =SUM(C24:E24) -> 1000000 | G24: =F24=H24 -> TRUE | H24: ='DETAILS (sorted)'!BI17 -> 1000000 | I24: 1700000 | J24: =H24/I24 -> 0.58823529 | K24: =MAX(I24-H24,0) -> 700000 | L24: =100%-J24 -> 0.41176471 | O24: =F24=H24 -> TRUE | P24: 1
A25: =A24+1 -> 17 | B25: Emanuel Moshi | C25: 200000 | D25: 100000 | E25: 900000 | F25: =SUM(C25:E25) -> 1200000 | G25: =F25=H25 -> FALSE | H25: ='DETAILS (sorted)'!BI18 -> 1800000 | I25: 1700000 | J25: =H25/I25 -> 1.0588235 | K25: =MAX(I25-H25,0) -> 0 | L25: =100%-J25 -> -0.058823529 | O25: =F25=H25 -> FALSE | P25: 1
A26: =A25+1 -> 18 | B26: Emmanuel Matechi | C26: 200000 | D26: 100000 | E26: 700000 | F26: =SUM(C26:E26) -> 1000000 | G26: =F26=H26 -> TRUE | H26: ='DETAILS (sorted)'!BI19 -> 1000000 | I26: 1700000 | J26: =H26/I26 -> 0.58823529 | K26: =MAX(I26-H26,0) -> 700000 | L26: =100%-J26 -> 0.41176471 | O26: =F26=H26 -> TRUE | P26: 1
A27: =A26+1 -> 19 | B27: Emmanuel Matee | C27: 200000 | D27: 100000 | E27: 1000000 | F27: =SUM(C27:E27) -> 1300000 | G27: =F27=H27 -> FALSE | H27: ='DETAILS (sorted)'!BI20 -> 1500000 | I27: 1700000 | J27: =H27/I27 -> 0.88235294 | K27: =MAX(I27-H27,0) -> 200000 | L27: =100%-J27 -> 0.11764706 | O27: =F27=H27 -> FALSE | P27: 1
A28: =A27+1 -> 20 | B28: Emmanuel Mmari | C28: 200000 | D28: 100000 | E28: 700000 | F28: =SUM(C28:E28) -> 1000000 | G28: =F28=H28 -> FALSE | H28: ='DETAILS (sorted)'!BI21 -> 1900000 | I28: 1700000 | J28: =H28/I28 -> 1.1176471 | K28: =MAX(I28-H28,0) -> 0 | L28: =100%-J28 -> -0.11764706 | O28: =F28=H28 -> FALSE | P28: 1
A29: =A28+1 -> 21 | B29: Emmanuel Msaki | C29: 200000 | D29: 100000 | E29: 213000 | F29: =SUM(C29:E29) -> 513000 | G29: =F29=H29 -> FALSE | H29: ='DETAILS (sorted)'!BI22 -> 1900000 | I29: 1700000 | J29: =H29/I29 -> 1.1176471 | K29: =MAX(I29-H29,0) -> 0 | L29: =100%-J29 -> -0.11764706 | O29: =F29=H29 -> FALSE
A30: =A29+1 -> 22 | B30: Erick Kitali | C30: 200000 | D30: 100000 | E30: 1000000 | F30: =SUM(C30:E30) -> 1300000 | G30: =F30=H30 -> FALSE | H30: ='DETAILS (sorted)'!BI23 -> 1500000 | I30: 1700000 | J30: =H30/I30 -> 0.88235294 | K30: =MAX(I30-H30,0) -> 200000 | L30: =100%-J30 -> 0.11764706 | O30: =F30=H30 -> FALSE | P30: 1
A31: =A30+1 -> 23 | B31: Ernest Felician Shirima | C31: 200000 | D31: 100000 | E31: 500000 | F31: =SUM(C31:E31) -> 800000 | G31: =F31=H31 -> FALSE | H31: ='DETAILS (sorted)'!BI24 -> 2100000 | I31: 1700000 | J31: =H31/I31 -> 1.2352941 | K31: =MAX(I31-H31,0) -> 0 | L31: =100%-J31 -> -0.23529412 | O31: =F31=H31 -> FALSE
A32: =A31+1 -> 24 | B32: Evance Mori | C32: 200000 | D32: 100000 | E32: 700000 | F32: =SUM(C32:E32) -> 1000000 | G32: =F32=H32 -> FALSE | H32: ='DETAILS (sorted)'!BI25 -> 2000000 | I32: 1700000 | J32: =H32/I32 -> 1.1764706 | K32: =MAX(I32-H32,0) -> 0 | L32: =100%-J32 -> -0.17647059 | O32: =F32=H32 -> FALSE | P32: 1
A33: =A32+1 -> 25 | B33: Evarist Exavery Francisco | C33: 200000 | D33: 100000 | E33: 700000 | F33: =SUM(C33:E33) -> 1000000 | G33: =F33=H33 -> TRUE | H33: ='DETAILS (sorted)'!BI26 -> 1000000 | I33: 1700000 | J33: =H33/I33 -> 0.58823529 | K33: =MAX(I33-H33,0) -> 700000 | L33: =100%-J33 -> 0.41176471 | O33: =F33=H33 -> TRUE | P33: 1
A34: =A33+1 -> 26 | B34: Felix Daniel | C34: 141000 | F34: =SUM(C34:E34) -> 141000 | G34: =F34=H34 -> FALSE | H34: ='DETAILS (sorted)'!BI27 -> 1900000 | I34: 1700000 | J34: =H34/I34 -> 1.1176471 | K34: =MAX(I34-H34,0) -> 0 | L34: =100%-J34 -> -0.11764706 | O34: =F34=H34 -> FALSE
A35: =A34+1 -> 27 | B35: Fredrick Peter Ndossi | C35: 200000 | D35: 100000 | E35: 700000 | F35: =SUM(C35:E35) -> 1000000 | G35: =F35=H35 -> TRUE | H35: ='DETAILS (sorted)'!BI28 -> 1000000 | I35: 1700000 | J35: =H35/I35 -> 0.58823529 | K35: =MAX(I35-H35,0) -> 700000 | L35: =100%-J35 -> 0.41176471 | N35: 10000 | O35: =F35=H35 -> TRUE | P35: 1
A36: =A35+1 -> 28 | B36: Gideon Gabriel | C36: 200000 | D36: 100000 | E36: 70000 | F36: =SUM(C36:E36) -> 370000 | G36: =F36=H36 -> FALSE | H36: ='DETAILS (sorted)'!BI29 -> 1700000 | I36: 1700000 | J36: =H36/I36 -> 1 | K36: =MAX(I36-H36,0) -> 0 | L36: =100%-J36 -> 0 | O36: =F36=H36 -> FALSE
A37: =A36+1 -> 29 | B37: Hassan Matata | C37: 200000 | D37: 100000 | E37: 700000 | F37: =SUM(C37:E37) -> 1000000 | G37: =F37=H37 -> FALSE | H37: ='DETAILS (sorted)'!BI30 -> 1400000 | I37: 1700000 | J37: =H37/I37 -> 0.82352941 | K37: =MAX(I37-H37,0) -> 300000 | L37: =100%-J37 -> 0.17647059 | O37: =F37=H37 -> FALSE | P37: 1
A38: =A37+1 -> 30 | B38: Innocent Kasigwa | C38: 200000 | D38: 100000 | E38: 700000 | F38: =SUM(C38:E38) -> 1000000 | G38: =F38=H38 -> FALSE | H38: ='DETAILS (sorted)'!BI31 -> 1500000 | I38: 1700000 | J38: =H38/I38 -> 0.88235294 | K38: =MAX(I38-H38,0) -> 200000 | L38: =100%-J38 -> 0.11764706 | O38: =F38=H38 -> FALSE | P38: 1
A39: =A38+1 -> 31 | B39: Innocent Kweka | C39: 160000 | F39: =SUM(C39:E39) -> 160000 | G39: =F39=H39 -> FALSE | H39: ='DETAILS (sorted)'!BI32 -> 1020000 | I39: 1700000 | J39: =H39/I39 -> 0.6 | K39: =MAX(I39-H39,0) -> 680000 | L39: =100%-J39 -> 0.4 | O39: =F39=H39 -> FALSE
A40: =A39+1 -> 32 | B40: Innocent Mosha | C40: 200000 | D40: 100000 | E40: 700000 | F40: =SUM(C40:E40) -> 1000000 | G40: =F40=H40 -> FALSE | H40: ='DETAILS (sorted)'!BI33 -> 1200000 | I40: 1700000 | J40: =H40/I40 -> 0.70588235 | K40: =MAX(I40-H40,0) -> 500000 | L40: =100%-J40 -> 0.29411765 | P40: 1
A41: =A40+1 -> 33 | B41: Jacob Mangu | C41: 200000 | D41: 100000 | E41: 1300000 | F41: =SUM(C41:E41) -> 1600000 | G41: =F41=H41 -> FALSE | H41: ='DETAILS (sorted)'!BI34 -> 1000000 | I41: 1700000 | J41: =H41/I41 -> 0.58823529 | K41: =MAX(I41-H41,0) -> 700000 | L41: =100%-J41 -> 0.41176471 | O41: =F41=H41 -> FALSE | P41: 1
A42: =A41+1 -> 34 | B42: John Massawe | C42: 200000 | D42: 100000 | E42: 700000 | F42: =SUM(C42:E42) -> 1000000 | G42: =F42=H42 -> TRUE | H42: ='DETAILS (sorted)'!BI35 -> 1000000 | I42: 1700000 | J42: =H42/I42 -> 0.58823529 | K42: =MAX(I42-H42,0) -> 700000 | L42: =100%-J42 -> 0.41176471 | O42: =F42=H42 -> TRUE | P42: 1
A43: =A42+1 -> 35 | B43: Kanuti S. Simba | C43: 200000 | D43: 100000 | E43: 700000 | F43: =SUM(C43:E43) -> 1000000 | G43: =F43=H43 -> TRUE | H43: ='DETAILS (sorted)'!BI36 -> 1000000 | I43: 1700000 | J43: =H43/I43 -> 0.58823529 | K43: =MAX(I43-H43,0) -> 700000 | L43: =100%-J43 -> 0.41176471 | O43: =F43=H43 -> TRUE | P43: 1
...

Sheet Summary2
A1: ILBORU ALUMNI SACCOS LIMITED
A3: MICHANGO YA WANACHAMA
A6: S/N | B6: Member Name | C6: MICHANGO
C7: KIINGILIO | D7: AKIBA | E7: HISA | F7: JUMLA | H7: ACTUAL | I7: KIINGILIO | J7: SHARES (50%) | K7: OCTOBER, 2024 | L7: NOV, 2024 | M7: DEC, 2024 | N7: JAN, 2025 | O7: FEB, 2025 | P7: TOTAL | Q7: STATUS
D8: ALLOCATED FROM M-KOBA | E8: ALLOCATED FROM M-KOBA | H8: MKOBA
A9: 1 | B9: Aaron J. Mtui | C9: 100000 | F9: =SUM(C9:E9) -> 100000 | G9: =F9=H9 -> TRUE | H9: =Summary!H9 -> 100000 | I9: 200000 | J9: 500000 | K9: 100000 | L9: 100000 | M9: 100000 | N9: 100000 | O9: 100000 | P9: =SUM(I9:O9) -> 1200000 | Q9: =H9-P9 -> -1100000
A10: =A9+1 -> 2 | B10: Abduel G. Kitururu | C10: 200000 | D10: 100000 | E10: 330000 | F10: =SUM(C10:E10) -> 630000 | G10: =F10=H10 -> TRUE | H10: =Summary!H10 -> 630000 | I10: 200000 | J10: 500000 | K10: 100000 | L10: 100000 | M10: 100000 | N10: 100000 | O10: 100000 | P10: =SUM(I10:O10) -> 1200000 | Q10: =H10-P10 -> -570000
A11: =A10+1 -> 3 | B11: Abraham A. Assenga | C11: 200000 | D11: 100000 | E11: 700000 | F11: =SUM(C11:E11) -> 1000000 | G11: =F11=H11 -> TRUE | H11: =Summary!H11 -> 1000000 | I11: 200000 | J11: 500000 | K11: 100000 | L11: 100000 | M11: 100000 | N11: 100000 | O11: 100000 | P11: =SUM(I11:O11) -> 1200000 | Q11: =H11-P11 -> -200000
A12: =A11+1 -> 4 | B12: Adam I. Urassa | C12: 200000 | D12: 100000 | E12: 700000 | F12: =SUM(C12:E12) -> 1000000 | G12: =F12=H12 -> TRUE | H12: =Summary!H12 -> 1000000 | I12: 200000 | J12: 500000 | K12: 100000 | L12: 100000 | M12: 100000 | N12: 100000 | O12: 100000 | P12: =SUM(I12:O12) -> 1200000 | Q12: =H12-P12 -> -200000
A13: =A12+1 -> 5 | B13: Amos M. Nungu | C13: 200000 | D13: 100000 | E13: 700000 | F13: =SUM(C13:E13) -> 1000000 | G13: =F13=H13 -> TRUE | H13: =Summary!H13 -> 1000000 | I13: 200000 | J13: 500000 | K13: 100000 | L13: 100000 | M13: 100000 | N13: 100000 | O13: 100000 | P13: =SUM(I13:O13) -> 1200000 | Q13: =H13-P13 -> -200000
A14: =A13+1 -> 6 | B14: Athumani Jerry Mwasha | C14: 200000 | D14: 100000 | E14: 700000 | F14: =SUM(C14:E14) -> 1000000 | G14: =F14=H14 -> TRUE | H14: =Summary!H14 -> 1000000 | I14: 200000 | J14: 500000 | K14: 100000 | L14: 100000 | M14: 100000 | N14: 100000 | O14: 100000 | P14: =SUM(I14:O14) -> 1200000 | Q14: =H14-P14 -> -200000
A15: =A14+1 -> 7 | B15: Elianshisaria Invocavith Munisi | C15: 200000 | D15: 100000 | E15: 920000 | F15: =SUM(C15:E15) -> 1220000 | G15: =F15=H15 -> TRUE | H15: =Summary!H15 -> 1220000 | I15: 200000 | J15: 500000 | K15: 100000 | L15: 100000 | M15: 100000 | N15: 100000 | O15: 100000 | P15: =SUM(I15:O15) -> 1200000 | Q15: =H15-P15 -> 20000
A16: =A15+1 -> 8 | B16: Elibariki Mkumbo | C16: 200000 | D16: 100000 | E16: 700000 | F16: =SUM(C16:E16) -> 1000000 | G16: =F16=H16 -> TRUE | H16: =Summary!H16 -> 1000000 | I16: 200000 | J16: 500000 | K16: 100000 | L16: 100000 | M16: 100000 | N16: 100000 | O16: 100000 | P16: =SUM(I16:O16) -> 1200000 | Q16: =H16-P16 -> -200000
A17: =A16+1 -> 9 | B17: Emmanuel Matechi | C17: 200000 | D17: 100000 | E17: 700000 | F17: =SUM(C17:E17) -> 1000000 | G17: =F17=H17 -> TRUE | H17: =Summary!H17 -> 1000000 | I17: 200000 | J17: 500000 | K17: 100000 | L17: 100000 | M17: 100000 | N17: 100000 | O17: 100000 | P17: =SUM(I17:O17) -> 1200000 | Q17: =H17-P17 -> -200000
A18: =A17+1 -> 10 | B18: Emmanuel Matee | C18: 200000 | D18: 100000 | E18: 1000000 | F18: =SUM(C18:E18) -> 1300000 | G18: =F18=H18 -> TRUE | H18: =Summary!H18 -> 1300000 | I18: 200000 | J18: 500000 | K18: 100000 | L18: 100000 | M18: 100000 | N18: 100000 | O18: 100000 | P18: =SUM(I18:O18) -> 1200000 | Q18: =H18-P18 -> 100000
A19: =A18+1 -> 11 | B19: Emmanuel Mmari | C19: 200000 | D19: 100000 | E19: 700000 | F19: =SUM(C19:E19) -> 1000000 | G19: =F19=H19 -> TRUE | H19: =Summary!H19 -> 1000000 | I19: 200000 | J19: 500000 | K19: 100000 | L19: 100000 | M19: 100000 | N19: 100000 | O19: 100000 | P19: =SUM(I19:O19) -> 1200000 | Q19: =H19-P19 -> -200000
A20: =A19+1 -> 12 | B20: Erick Kitali | C20: 200000 | D20: 100000 | E20: 700000 | F20: =SUM(C20:E20) -> 1000000 | G20: =F20=H20 -> FALSE | H20: =Summary!H20 -> 1300000 | I20: 200000 | J20: 500000 | K20: 100000 | L20: 100000 | M20: 100000 | N20: 100000 | O20: 100000 | P20: =SUM(I20:O20) -> 1200000 | Q20: =H20-P20 -> 100000
A21: =A20+1 -> 13 | B21: Ernest Felician Shirima | C21: 200000 | D21: 100000 | E21: 500000 | F21: =SUM(C21:E21) -> 800000 | G21: =F21=H21 -> TRUE | H21: =Summary!H21 -> 800000 | I21: 200000 | J21: 500000 | K21: 100000 | L21: 100000 | M21: 100000 | N21: 100000 | O21: 100000 | P21: =SUM(I21:O21) -> 1200000 | Q21: =H21-P21 -> -400000
... A34: =A33+1 -> 26 | B34: Charles Jangu | C34: 200000 | D34: 100000 | E34: 400000 | F34: =SUM(C34:E34) -> 700000 | G34: =F34=H34 -> TRUE | H34: =Summary!H34 -> 700000 | I34: 200000 | J34: 500000 | K34: 100000 | L34: 100000 | M34: 100000 | N34: 100000 | O34: 100000 | P34: =SUM(I34:O34) -> 1200000 | Q34: =H34-P34 -> -500000
A35: =A34+1 -> 27 | B35: David Koillah | C35: 100000 | F35: =SUM(C35:E35) -> 100000 | G35: =F35=H35 -> TRUE | H35: =Summary!H35 -> 100000 | I35: 200000 | J35: 500000 | K35: 100000 | L35: 100000 | M35: 100000 | N35: 100000 | O35: 100000 | P35: =SUM(I35:O35) -> 1200000 | Q35: =H35-P35 -> -1100000
A36: =A35+1 -> 28 | B36: Emmanuel Msaki | C36: 200000 | D36: 100000 | E36: 213000 | F36: =SUM(C36:E36) -> 513000 | G36: =F36=H36 -> TRUE | H36: =Summary!H36 -> 513000 | I36: 200000 | J36: 500000 | K36: 100000 | L36: 100000 | M36: 100000 | N36: 100000 | O36: 100000 | P36: =SUM(I36:O36) -> 1200000 | Q36: =H36-P36 -> -687000
A37: =A36+1 -> 29 | B37: Evance Mori | C37: 200000 | D37: 100000 | E37: 700000 | F37: =SUM(C37:E37) -> 1000000 | G37: =F37=H37 -> TRUE | H37: =Summary!H37 -> 1000000 | I37: 200000 | J37: 500000 | K37: 100000 | L37: 100000 | M37: 100000 | N37: 100000 | O37: 100000 | P37: =SUM(I37:O37) -> 1200000 | Q37: =H37-P37 -> -200000
A38: =A37+1 -> 30 | B38: Felix Daniel | C38: 141000 | F38: =SUM(C38:E38) -> 141000 | G38: =F38=H38 -> TRUE | H38: =Summary!H38 -> 141000 | I38: 200000 | J38: 500000 | K38: 100000 | L38: 100000 | M38: 100000 | N38: 100000 | O38: 100000 | P38: =SUM(I38:O38) -> 1200000 | Q38: =H38-P38 -> -1059000
A39: =A38+1 -> 31 | B39: Gideon Gabriel | C39: 200000 | D39: 100000 | E39: 70000 | F39: =SUM(C39:E39) -> 370000 | G39: =F39=H39 -> TRUE | H39: =Summary!H39 -> 370000 | I39: 200000 | J39: 500000 | K39: 100000 | L39: 100000 | M39: 100000 | N39: 100000 | O39: 100000 | P39: =SUM(I39:O39) -> 1200000 | Q39: =H39-P39 -> -830000
A40: =A39+1 -> 32 | B40: Hassan Matata | C40: 200000 | D40: 100000 | E40: 700000 | F40: =SUM(C40:E40) -> 1000000 | G40: =F40=H40 -> TRUE | H40: =Summary!H40 -> 1000000 | I40: 200000 | J40: 500000 | K40: 100000 | L40: 100000 | M40: 100000 | N40: 100000 | O40: 100000 | P40: =SUM(I40:O40) -> 1200000 | Q40: =H40-P40 -> -200000
A41: =A40+1 -> 33 | B41: Innocent Kasigwa | C41: 200000 | D41: 100000 | E41: 700000 | F41: =SUM(C41:E41) -> 1000000 | G41: =F41=H41 -> TRUE | H41: =Summary!H41 -> 1000000 | I41: 200000 | J41: 500000 | K41: 100000 | L41: 100000 | M41: 100000 | N41: 100000 | O41: 100000 | P41: =SUM(I41:O41) -> 1200000 | Q41: =H41-P41 -> -200000
A42: =A41+1 -> 34 | B42: Innocent Kweka | C42: 160000 | F42: =SUM(C42:E42) -> 160000 | G42: =F42=H42 -> TRUE | H42: =Summary!H42 -> 160000 | I42: 200000 | J42: 500000 | K42: 100000 | L42: 100000 | M42: 100000 | N42: 100000 | O42: 100000 | P42: =SUM(I42:O42) -> 1200000 | Q42: =H42-P42 -> -1040000
A43: =A42+1 -> 35 | B43: Jacob Mangu | C43: 200000 | D43: 100000 | E43: 1300000 | F43: =SUM(C43:E43) -> 1600000 | G43: =F43=H43 -> TRUE | H43: =Summary!H43 -> 1600000 | I43: 200000 | J43: 500000 | K43: 100000 | L43: 100000 | M43: 100000 | N43: 100000 | O43: 100000 | P43: =SUM(I43:O43) -> 1200000 | Q43: =H43-P43 -> 400000
A44: =A43+1 -> 36 | B44: John Massawe | C44: 200000 | D44: 100000 | E44: 700000 | F44: =SUM(C44:E44) -> 1000000 | G44: =F44=H44 -> TRUE | H44: =Summary!H44 -> 1000000 | I44: 200000 | J44: 500000 | K44: 100000 | L44: 100000 | M44: 100000 | N44: 100000 | O44: 100000 | P44: =SUM(I44:O44) -> 1200000 | Q44: =H44-P44 -> -200000
A45: =A44+1 -> 37 | B45: Khalifa Sushy | C45: 200000 | D45: 100000 | E45: 120000 | F45: =SUM(C45:E45) -> 420000 | G45: =F45=H45 -> TRUE | H45: =Summary!H45 -> 420000 | I45: 200000 | J45: 500000 | K45: 100000 | L45: 100000 | M45: 100000 | N45: 100000 | O45: 100000 | P45: =SUM(I45:O45) -> 1200000 | Q45: =H45-P45 -> -780000
A46: =A45+1 -> 38 | B46: Laurian Gidoyi | C46: 200000 | D46: 100000 | E46: 700000 | F46: =SUM(C46:E46) -> 1000000 | G46: =F46=H46 -> TRUE | H46: =Summary!H46 -> 1000000 | I46: 200000 | J46: 500000 | K46: 100000 | L46: 100000 | M46: 100000 | N46: 100000 | O46: 100000 | P46: =SUM(I46:O46) -> 1200000 | Q46: =H46-P46 -> -200000
A47: =A46+1 -> 39 | B47: Liggyle Vumilia | C47: 200000 | D47: 100000 | E47: 50000 | F47: =SUM(C47:E47) -> 350000 | G47: =F47=H47 -> TRUE | H47: =Summary!H47 -> 350000 | I47: 200000 | J47: 500000 | K47: 100000 | L47: 100000 | M47: 100000 | N47: 100000 | O47: 100000 | P47: =SUM(I47:O47) -> 1200000 | Q47: =H47-P47 -> -850000
A48: =A47+1 -> 40 | B48: Masale Masale | C48: 200000 | D48: 100000 | E48: 700000 | F48: =SUM(C48:E48) -> 1000000 | G48: =F48=H48 -> TRUE | H48: =Summary!H48 -> 1000000 | I48: 200000 | J48: 500000 | K48: 100000 | L48: 100000 | M48: 100000 | N48: 100000 | O48: 100000 | P48: =SUM(I48:O48) -> 1200000 | Q48: =H48-P48 -> -200000
A49: =A48+1 -> 41 | B49: Nalogwa Kiula | C49: 50000 | F49: =SUM(C49:E49) -> 50000 | G49: =F49=H49 -> TRUE | H49: =Summary!H49 -> 50000 | I49: 200000 | J49: 500000 | K49: 100000 | L49: 100000 | M49: 100000 | N49: 100000 | O49: 100000 | P49: =SUM(I49:O49) -> 1200000 | Q49: =H49-P49 -> -1150000
A50: =A49+1 -> 42 | B50: Nixon Matowo | C50: 200000 | D50: 100000 | E50: 710000 | F50: =SUM(C50:E50) -> 1010000 | G50: =F50=H50 -> TRUE | H50: =Summary!H50 -> 1010000 | I50: 200000 | J50: 500000 | K50: 100000 | L50: 100000 | M50: 100000 | N50: 100000 | O50: 100000 | P50: =SUM(I50:O50) -> 1200000 | Q50: =H50-P50 -> -190000
A51: =A50+1 -> 43 | B51: Norbert Massay | C51: 200000 | D51: 100000 | E51: 700000 | F51: =SUM(C51:E51) -> 1000000 | G51: =F51=H51 -> FALSE | H51: =Summary!H51 -> 1200000 | I51: 200000 | J51: 500000 | K51: 100000 | L51: 100000 | M51: 100000 | N51: 100000 | O51: 100000 | P51: =SUM(I51:O51) -> 1200000 | Q51: =H51-P51 -> 0
A52: =A51+1 -> 44 | B52: Omary Mwasema | C52: 50000 | F52: =SUM(C52:E52) -> 50000 | G52: =F52=H52 -> TRUE | H52: =Summary!H52 -> 50000 | I52: 200000 | J52: 500000 | K52: 100000 | L52: 100000 | M52: 100000 | N52: 100000 | O52: 100000 | P52: =SUM(I52:O52) -> 1200000 | Q52: =H52-P52 -> -1150000
A53: =A52+1 -> 45 | B53: Patiens Rweyemamu | C53: 100000 | F53: =SUM(C53:E53) -> 100000 | G53: =F53=H53 -> TRUE | H53: =Summary!H53 -> 100000 | I53: 200000 | J53: 500000 | K53: 100000 | L53: 100000 | M53: 100000 | N53: 100000 | O53: 100000 | P53: =SUM(I53:O53) -> 1200000 | Q53: =H53-P53 -> -1100000
A54: =A53+1 -> 46 | B54: Paul Metili | C54: 100000 | F54: =SUM(C54:E54) -> 100000 | G54: =F54=H54 -> TRUE | H54: =Summary!H54 -> 100000 | I54: 200000 | J54: 500000 | K54: 100000 | L54: 100000 | M54: 100000 | N54: 100000 | O54: 100000 | P54: =SUM(I54:O54) -> 1200000 | Q54: =H54-P54 -> -1100000
A55: =A54+1 -> 47 | B55: Robert Masegese | C55: 200000 | F55: =SUM(C55:E55) -> 200000 | G55: =F55=H55 -> TRUE | H55: =Summary!H55 -> 200000 | I55: 200000 | J55: 500000 | K55: 100000 | L55: 100000 | M55: 100000 | N55: 100000 | O55: 100000 | P55: =SUM(I55:O55) -> 1200000 | Q55: =H55-P55 -> -1000000
...

Sheet DETAILS (sorted)
A1: ID | B1: Member Name | C1: Phone number | D1: Date | E1: Amount 1 | F1: Type | G1: Date | H1: Amount 2 | I1: Type | J1: Date | K1: Amount 3 | L1: Type | M1: Date | N1: Amount 4 | O1: Type | P1: Date | Q1: Amount 5 | R1: Type | S1: Date | T1: Amount 6 | U1: Type | V1: Date | W1: Amount 7 | X1: Type | Y1: Date | Z1: Amount 8 | AA1: Type | AB1: Date | AC1: Amount 9 | AD1: Type | AE1: Date | AF1: Amount 10 | AG1: Type | AH1: Date | AI1: Amount 11 | AJ1: Type | AK1: Date | AL1: Amount 12 | AM1: Type | AN1: Date | AO1: Amount 13 | AP1: Type | AQ1: Date | AR1: Amount 14 | AS1: Type | AT1: Date | AU1: Amount 15 | AV1: Type | AW1: Date | AX1: Amount 16 | AY1: Type | AZ1: Date | BA1: Amount 17 | BB1: Type | BF1: Date | BG1: Amount 18 | BH1: Type | BI1: Grand Total Y1 | BJ1: Total Socio | BK1: NMB | BL1: Total Shares | BM1: Grand Total Y1 | BO1: OCT, 25 | BP1: Amount | BQ1: NOV, 25 | BR1: Amount | BS1: DEC, 25 | BT1: Amount | BU1: JAN, 26 | BV1: Amount | BW1: FEB, 26 | BX1: Amount | BY1: MAR, 26 | BZ1: 46082 | CA1: APR, 26 | CB1: 46113 | CC1: MAY, 26 | CD1: 46143 | CE1: JUN, 26 | CF1: Amount | CG1: JUL, 26 | CH1: Amount | CI1: AUG, 26 | CJ1: Amount | CK1: SEP, 26 | CL1: Amount | CM1: Grand Total Y2 | CN1: TOTAL contributions only Y1+Y2 | CO1: DIVIDEND 1 UTT (Year 1) | CP1: TOTAL UP TO 30 NOV. 25 | CQ1: DIV 2 UTT (Nov. 25) | CR1: DIV 3 (Loan 1) | CS1: TOTAL UP TO JAN 26 | CT1: DIV 4 UTT (Jan 24) | CU1: TOTAL UP TO FEB 26 | CV1: DIV 5 (Loan 2+3) | CW1: TOTAL UP TO MAR 26 | CX1: DIV 6 UTT (15 Apr 26) | CY1: TOTAL UP TO APR 26 | CZ1: LOAN 6+7 Apr 26 (250+500k) | DA1: DIV. 7 UTT 5th May 26 | DB1: TOTAL UP TO MAY 26 | DC1: DIV (loan 8,10, 11,12,5) 1 June 26 | DD1: DIV UTT 6: 2nd June 26 | DE1: TOTAL UP JUNE 2026 | DF1: DIV (loans June 2026) | DG1: DIV UTT 7 JUNE 2026 | DH1: TOTAL UP TO JULY 2026 | DI1: What is in Portal | DJ1: difference | DK1: DIV (Loans July 2026) | DL1: DIV UTT 8 -31 JULY2026 | DM1: TOTAL UP TO AUG 2026 | DN1: DIV (Loans Aug 2026) | DO1: DIV UTT 9 - 31 AUG 2026 | DP1: TOTAL UP TO SEPT 2026 | DQ1: DIV (Loans Sep 2026) | DR1: DIV UTT 9 - 30 SEP 2026 | DS1: CUMMULATIVE TOTAL | DU1: MEMBER NAME | DV1: TOTAL CONTRIBUTION | DW1: PROFIT TODATE | DZ1: TOTAL AMOUNT
A2: ILS24-F00001 | B2: Nsanyiwa Kiloba | C2: 0655281326 | D2: 45355 | E2: 170000 | F2: Shares | G2: 45355 | H2: 80000 | I2: Social | J2: 45361 | K2: 170000 | L2: Shares | M2: 45361 | N2: 90000 | O2: Social | P2: 45370 | R2: Shares | S2: 45655 | T2: 400000 | U2: Shares | V2: 45739 | W2: 100000 | X2: Shares | Y2: 45884 | Z2: 1000000 | AA2: NMB | AB2: 45912 | AC2: 190000 | AD2: NMB | BI2: =E2+H2+K2+N2+Q2+T2+W2+Z2+AC2+AF2+AI2+AO2+AL2+AR2+AU2+AX2+BA2+BG2 -> 2200000 | BJ2: =H2+N2 -> 170000 | BK2: =Z2+AC2 -> 1190000 | BL2: =E2+K2+Q2+T2+W2 -> 840000 | BM2: =BJ2+BL2+BK2 -> 2200000 | BN2: =BM2=BI2 -> TRUE | BO2: 45941 | BP2: =300000+200000 -> 500000 | BQ2: 45981 | BR2: 1000000 | BS2: 46014 | BT2: =100000+1200000 -> 1300000 | BU2: 46041 | BV2: =2000000+2000000 -> 4000000 | BW2: 46058 | BX2: =1000000+300000+500000 -> 1800000 | BY2: 46087 | BZ2: =125000+1200000+300000+700000+1300000+1000000+925225+1500000 -> 7050225 | CA2: 46113 | CB2: =3500000+1500000+3000000+326589 -> 8326589 | CC2: 46164 | CD2: =500000+355488+2000000 -> 2855488 | CE2: 46174 | CF2: =1000000+1500000+225500+500100+1000000+500000 -> 4725600 | CG2: 46212 | CH2: =2200000+2600000+1500000 -> 6300000 | CM2: =BP2+BR2+BT2+BV2+BX2+BZ2+CB2+CD2+CF2+CH2+CJ2+CL2 -> 37857902 | CN2: =BM2+CM2 -> 40057902 | CO2: =BM2/$BM$153*$BM$166 -> 32705.035 | CP2: =BM2+BP2+BR2 -> 3700000 | CQ2: =CP2/$CP$153*$DS$172 -> 48456.297 | CR2: =CP2/$CP$153*$DS$173 -> 73904.694 | CS2: =BM2+BP2+BR2+BT2+BV2 -> 9000000 | CT2: =CS2/$CS$153*$DS$174 -> 128015.05 | CU2: =CS2+BX2 -> 10800000 | CV2: =CU2/$CU$153*$DS$175 -> 366693.52 | CW2: =CU2+BZ2 -> 17850225 | CX2: =CW2/$CW$153*$DS$176 -> 173411.72 | CY2: =CW2+CB2 -> 26176814 | CZ2: =CY2/$CY$153*750000 -> 40449.761 | DA2: =CY2/$CY$153*$DS$185 -> 104062.18 | DB2: =CY2+CD2 -> 29032302 | DC2: =DB2/$DB$153*$DC$154 -> 163616.32 | DD2: =DB2/$DB$153*$DD$154 -> 110783.79 | DE2: =DB2+CF2 -> 33757902 | DF2: =DE2/$DE$153*$DF$154 -> 90512.651 | DG2: =DE2/$DE$153*$DG$154 -> 302221.05 | DH2: =40192734.0611326+1500000 -> 41692734 | DI2: =DH2 -> 41692734 | DJ2: =DH2-DI2 -> 0 | DK2: =DH2/$DH$153*$DK$154 -> 428090.97 | DL2: =DH2/$DH$153*$DL$154 -> 119243.37 | DS2: =CN2+CO2+CQ2+CR2+CT2+CV2+CX2+CZ2+DA2+DC2+DD2+DF2+DG2+DK2+DL2+DN2+DO2+DQ2+DR2 -> 42240068 | DT2: =DS2=CN2+CO2+CQ2+CR2+CT2+CV2+CX2+CZ2+DA2+DC2+DD2+DF2+DG2+DK2+DL2+DN2+DO2+DQ2+DR2 -> TRUE | DU2: =B2 -> Nsanyiwa Kiloba | DV2: =DS2 -> 42240068 | DW2: =DS2-CN2 -> 2182166.4 | DZ2: =BM2+BP2+BR2+BT2+CO2+CQ2+CR2+CT2 -> 5283081.1 | EB2: =BM2+BP2+BR2+BT2+BV2+BX2+CO2+CQ2+CR2+CT2+CV2 -> 11449775
A3: ILS24-F00002 | B3: Werema Msongo | C3: 0764636000 | D3: 45370 | E3: 530000 | F3: Shares | G3: 45370 | H3: 230000 | I3: Social | J3: 45523 | K3: 40000 | L3: Shares | M3: 45884 | N3: 1000000 | O3: NMB | P3: 45885 | Q3: 500000 | R3: UTT | S3: 45905 | T3: 400000 | U3: NMB | V3: 45911 | W3: 500000 | X3: NMB | Y3: 45915 | Z3: 300000 | AA3: NMB | BI3: =E3+H3+K3+N3+Q3+T3+W3+Z3+AC3+AF3+AI3+AO3+AL3+AR3+AU3+AX3+BA3+BG3 -> 3500000 | BJ3: =H3 -> 230000 | BK3: =N3+Q3+T3+W3+Z3 -> 2700000 | BL3: =E3+K3 -> 570000 | BM3: =BJ3+BL3+BK3 -> 3500000 | BN3: =BM3=BI3 -> TRUE | BO3: 45934 | BP3: =1000000+500000+1000000 -> 2500000 | BQ3: 45980 | BR3: =1500000+100000 -> 1600000 | BS3: 46014 | BT3: =3000000-2000000 -> 1000000 | BU3: 46052 | BV3: 200000 | BY3: 46084 | BZ3: =2500000+3000000+1500000+1500000+1000000+1160000+500000+1000000+1000000 -> 13160000 | CG3: 46228 | CH3: =1500000+2000000 -> 3500000 | CM3: =BP3+BR3+BT3+BV3+BX3+BZ3+CB3+CD3+CF3+CH3+CJ3+CL3 -> 21960000 | CN3: =BM3+CM3 -> 25460000 | CO3: =BM3/$BM$153*$BM$166 -> 52030.738 | CP3: =BM3+BP3+BR3 -> 7600000 | CQ3: =CP3/$CP$153*$DS$172 -> 99531.852 | CR3: =CP3/$CP$153*$DS$173 -> 151804.24 | CS3: =BM3+BP3+BR3+BT3+BV3 -> 8800000 | CT3: =CS3/$CS$153*$DS$174 -> 125170.27 | CU3: =CS3+BX3 -> 8800000 | CV3: =CU3/$CU$153*$DS$175 -> 298787.32 | CW3: =CU3+BZ3 -> 21960000 | CX3: =CW3/$CW$153*$DS$176 -> 213337.44 | CY3: =CW3+CB3 -> 21960000 | CZ3: =CY3/$CY$153*750000 -> 33933.723 | DA3: =CY3/$CY$153*$DS$185 -> 87298.842 | DB3: =CY3+CD3 -> 21960000 | DC3: =DB3/$DB$153*$DC$154 -> 123759.2 | DD3: =DB3/$DB$153*$DD$154 -> 83796.73 | DE3: =DB3+CF3 -> 21960000 | DF3: =DE3/$DE$153*$DF$154 -> 58879.779 | DG3: =DE3/$DE$153*$DG$154 -> 196599.13 | DH3: 26984929 | DI3: =DH3 -> 26984929 | DJ3: =DH3-DI3 -> 0 | DK3: =DH3/$DH$153*$DK$154 -> 277074.77 | DL3: =DH3/$DH$153*$DL$154 -> 77178.289 | DS3: =CN3+CO3+CQ3+CR3+CT3+CV3+CX3+CZ3+DA3+DC3+DD3+DF3+DG3+DK3+DL3+DN3+DO3+DQ3+DR3 -> 27339182 | DT3: =DS3=CN3+CO3+CQ3+CR3+CT3+CV3+CX3+CZ3+DA3+DC3+DD3+DF3+DG3+DK3+DL3+DN3+DO3+DQ3+DR3 -> TRUE | DU3: =B3 -> Werema Msongo | DV3: =DS3 -> 27339182 | DW3: =DS3-CN3 -> 1879182.3 | DZ3: =BM3+BP3+BR3+BT3+CO3+CQ3+CR3+CT3 -> 9028537.1 | EB3: =BM3+BP3+BR3+BT3+BV3+BX3+CO3+CQ3+CR3+CT3+CV3 -> 9527324.4
